<?xml version="1.0"?>
<robot name="gen3_arm" xmlns:xacro="http://www.ros.org/wiki/xacro">

  <material name="aluminum">
    <color rgba="0.5 0.5 0.5 1"/>
  </material>
  <material name="plastic">
    <color rgba="0.1 0.1 0.1 1"/>
  </material>

  <link name="world"/>

  <joint name="gen3_base_joint" type="fixed">
    <origin rpy="0 0 0" xyz="0 0 0"/>
    <parent link="world"/>
    <child link="gen3_base_link"/>
  </joint>
  <link name="gen3_base_link">
    <inertial>
      <origin rpy="0 0 0" xyz="-0.000648 -0.000166 0.084487"/>
      <mass value="1.697"/>
      <inertia ixx="0.004622" ixy="9E-06" ixz="6E-05" iyy="0.004495" iyz="9E-06" izz="0.002079"/>
    </inertial>
    <visual>
      <origin rpy="0 0 0" xyz="0 0 0"/>
      <geometry>
        <mesh filename="package://gen3_description/meshes/gen3_arm_visual/base_link.dae"/>
      </geometry>
      <material name=""><color rgba="0.75294 0.75294 0.75294 1"/></material>
    </visual>
    <collision>
      <origin rpy="0 0 0" xyz="0 0 0"/>
      <geometry><mesh filename="package://gen3_description/meshes/gen3_arm_collision/base_link.STL"/></geometry>
    </collision>
  </link>

  <link name="gen3_shoulder_link">
    <inertial>
      <origin rpy="0 0 0" xyz="-2.3E-05 -0.010364 -0.07336"/>
      <mass value="1.3773"/>
      <inertia ixx="0.00457" ixy="1E-06" ixz="2E-06" iyy="0.004831" iyz="0.000448" izz="0.001409"/>
    </inertial>
    <visual>
      <origin rpy="0 0 0" xyz="0 0 0"/>
      <geometry><mesh filename="package://gen3_description/meshes/gen3_arm_visual/shoulder_link.dae"/></geometry>
      <material name=""><color rgba="0.75294 0.75294 0.75294 1"/></material>
    </visual>
    <collision>
      <origin rpy="0 0 0" xyz="0 0 0"/>
      <geometry><mesh filename="package://gen3_description/meshes/gen3_arm_collision/shoulder_link.STL"/></geometry>
    </collision>
  </link>
  <joint name="gen3_joint_1" type="continuous">
    <origin rpy="3.1416 0 0" xyz="0 0 0.15643"/>
    <parent link="gen3_base_link"/>
    <child link="gen3_shoulder_link"/>
    <axis xyz="0 0 1"/>
    <limit effort="39" velocity="1.3963"/>
  </joint>

  <link name="gen3_half_arm_1_link">
    <inertial>
      <origin rpy="0 0 0" xyz="-4.4E-05 -0.09958 -0.013278"/>
      <mass value="1.1636"/>
      <inertia ixx="0.011088" ixy="5E-06" ixz="0" iyy="0.001072" iyz="-0.000691" izz="0.011255"/>
    </inertial>
    <visual>
      <origin rpy="0 0 0" xyz="0 0 0"/>
      <geometry><mesh filename="package://gen3_description/meshes/gen3_arm_visual/half_arm_1_link.dae"/></geometry>
      <material name=""><color rgba="0.75294 0.75294 0.75294 1"/></material>
    </visual>
    <collision>
      <origin rpy="0 0 0" xyz="0 0 0"/>
      <geometry><mesh filename="package://gen3_description/meshes/gen3_arm_collision/half_arm_1_link.STL"/></geometry>
    </collision>
  </link>
  <joint name="gen3_joint_2" type="revolute">
    <origin rpy="1.5708 0 0" xyz="0 0.005375 -0.12838"/>
    <parent link="gen3_shoulder_link"/>
    <child link="gen3_half_arm_1_link"/>
    <axis xyz="0 0 1"/>
    <limit effort="39" lower="-2.41" upper="2.41" velocity="1.3963"/>
  </joint>
  <link name="gen3_half_arm_2_link">
    <inertial>
      <origin rpy="0 0 0" xyz="-4.4E-05 -0.006641 -0.117892"/>
      <mass value="1.1636"/>
      <inertia ixx="0.010932" ixy="0" ixz="-7E-06" iyy="0.011127" iyz="0.000606" izz="0.001043"/>
    </inertial>
    <visual>
      <origin rpy="0 0 0" xyz="0 0 0"/>
      <geometry><mesh filename="package://gen3_description/meshes/gen3_arm_visual/half_arm_2_link.dae"/></geometry>
      <material name=""><color rgba="0.75294 0.75294 0.75294 1"/></material>
    </visual>
    <collision>
      <origin rpy="0 0 0" xyz="0 0 0"/>
      <geometry><mesh filename="package://gen3_description/meshes/gen3_arm_collision/half_arm_2_link.STL"/></geometry>
    </collision>
  </link>
  <joint name="gen3_joint_3" type="continuous">
    <origin rpy="-1.5708 0 0" xyz="0 -0.21038 -0.006375"/>
    <parent link="gen3_half_arm_1_link"/>
    <child link="gen3_half_arm_2_link"/>
    <axis xyz="0 0 1"/>
    <limit effort="39" velocity="1.3963"/>
  </joint>
  <link name="gen3_forearm_link">
    <inertial>
      <origin rpy="0 0 0" xyz="-1.8E-05 -0.075478 -0.015006"/>
      <mass value="0.9302"/>
      <inertia ixx="0.008147" ixy="-1E-06" ixz="0" iyy="0.000631" iyz="-0.0005" izz="0.008316"/>
    </inertial>
    <visual>
      <origin rpy="0 0 0" xyz="0 0 0"/>
      <geometry><mesh filename="package://gen3_description/meshes/gen3_arm_visual/forearm_link.dae"/></geometry>
      <material name=""><color rgba="0.75294 0.75294 0.75294 1"/></material>
    </visual>
    <collision>
      <origin rpy="0 0 0" xyz="0 0 0"/>
      <geometry><mesh filename="package://gen3_description/meshes/gen3_arm_collision/forearm_link.STL"/></geometry>
    </collision>
  </link>
  <joint name="gen3_joint_4" type="revolute">
    <origin rpy="1.5708 0 0" xyz="0 0.006375 -0.21038"/>
    <parent link="gen3_half_arm_2_link"/>
    <child link="gen3_forearm_link"/>
    <axis xyz="0 0 1"/>
    <limit effort="39" lower="-2.66" upper="2.66" velocity="1.3963"/>
  </joint>

  <link name="gen3_spherical_wrist_1_link">
    <inertial>
      <origin rpy="0 0 0" xyz="1E-06 -0.009432 -0.063883"/>
      <mass value="0.6781"/>
      <inertia ixx="0.001596" ixy="0" ixz="0" iyy="0.001607" iyz="0.000256" izz="0.000399"/>
    </inertial>
    <visual>
      <origin rpy="0 0 0" xyz="0 0 0"/>
      <geometry><mesh filename="package://gen3_description/meshes/gen3_arm_visual/spherical_wrist_1_link.dae"/></geometry>
      <material name=""><color rgba="0.75294 0.75294 0.75294 1"/></material>
    </visual>
    <collision>
      <origin rpy="0 0 0" xyz="0 0 0"/>
      <geometry><mesh filename="package://gen3_description/meshes/gen3_arm_collision/spherical_wrist_1_link.STL"/></geometry>
    </collision>
  </link>
  <joint name="gen3_joint_5" type="continuous">
    <origin rpy="-1.5708 0 0" xyz="0 -0.20843 -0.006375"/>
    <parent link="gen3_forearm_link"/>
    <child link="gen3_spherical_wrist_1_link"/>
    <axis xyz="0 0 1"/>
    <limit effort="9" velocity="1.2218"/>
  </joint>
  <link name="gen3_spherical_wrist_2_link">
    <inertial>
      <origin rpy="0 0 0" xyz="1E-06 -0.045483 -0.00965"/>
      <mass value="0.6781"/>
      <inertia ixx="0.001641" ixy="0" ixz="0" iyy="0.00041" iyz="-0.000278" izz="0.001641"/>
    </inertial>
    <visual>
      <origin rpy="0 0 0" xyz="0 0 0"/>
      <geometry><mesh filename="package://gen3_description/meshes/gen3_arm_visual/spherical_wrist_2_link.dae"/></geometry>
      <material name=""><color rgba="0.75294 0.75294 0.75294 1"/></material>
    </visual>
    <collision>
      <origin rpy="0 0 0" xyz="0 0 0"/>
      <geometry><mesh filename="package://gen3_description/meshes/gen3_arm_collision/spherical_wrist_2_link.STL"/></geometry>
    </collision>
  </link>
  <joint name="gen3_joint_6" type="revolute">
    <origin rpy="1.5708 0 0" xyz="0 0.00017505 -0.10593"/>
    <parent link="gen3_spherical_wrist_1_link"/>
    <child link="gen3_spherical_wrist_2_link"/>
    <axis xyz="0 0 1"/>
    <limit effort="9" lower="-2.23" upper="2.23" velocity="1.2218"/>
  </joint>
  <link name="gen3_bracelet_link">
    <inertial>
      <origin rpy="0 0 0" xyz="-9.3E-05 0.000132 -0.022905"/>
      <mass value="0.364"/>
      <inertia ixx="0.000214" ixy="0" ixz="1E-06" iyy="0.000223" iyz="-2E-06" izz="0.00024"/>
    </inertial>
    <visual>
      <origin rpy="0 0 0" xyz="0 0 0"/>
      <geometry><mesh filename="package://gen3_description/meshes/gen3_arm_visual/bracelet_with_vision_link.dae"/></geometry>
      <material name=""><color rgba="0.75294 0.75294 0.75294 1"/></material>
    </visual>
    <collision>
      <origin rpy="0 0 0" xyz="0 0 0"/>
      <geometry><mesh filename="package://gen3_description/meshes/gen3_arm_collision/bracelet_with_vision_link.STL"/></geometry>
    </collision>
  </link>
  <joint name="gen3_joint_7" type="continuous">
    <origin rpy="-1.5708 0 0" xyz="0 -0.10593 -0.00017505"/>
    <parent link="gen3_spherical_wrist_2_link"/>
    <child link="gen3_bracelet_link"/>
    <axis xyz="0 0 1"/>
    <limit effort="9" velocity="1.2218"/>
  </joint>

  <link name="gen3_end_effector_link"/>
  <joint name="gen3_end_effector" type="fixed">
    <origin rpy="3.14159 0 0" xyz="0 0 -0.061525"/>
    <parent link="gen3_bracelet_link"/>
    <child link="gen3_end_effector_link"/>
  </joint>

</robot>