<?xml version="1.0"?>
<robot name="robotiq_gripper" xmlns:xacro="http://www.ros.org/wiki/xacro">

  <link name="gen3_robotiq_85_base_link">
    <visual>
      <geometry><mesh filename="package://gen3_description/meshes/g2f85_visual/robotiq_base.dae"/></geometry>
    </visual>
    <collision>
      <geometry><mesh filename="package://gen3_description/meshes/g2f85_collision/robotiq_base.stl"/></geometry>
    </collision>
    <inertial>
      <origin rpy="0 0 0" xyz="0.0 2.274e-05 0.03232288"/>
      <mass value="0.663"/>
      <inertia ixx="0.000516" ixy="2.9e-8" ixz="0.0" iyy="0.000588" iyz="-3.2e-7" izz="0.000394"/>
    </inertial>
  </link>
  <link name="gen3_robotiq_85_left_knuckle_link">
    <visual>
      <geometry><mesh filename="package://gen3_description/meshes/g2f85_visual/left_knuckle.dae"/></geometry>
    </visual>
    <collision>
      <geometry><mesh filename="package://gen3_description/meshes/g2f85_collision/left_knuckle.stl"/></geometry>
    </collision>
    <inertial>
      <origin rpy="0 0 0" xyz="0.0121 0.0002 -0.00058"/>
      <mass value="0.0138"/>
      <inertia ixx="3.5e-7" ixy="0.0" ixz="1.1e-7" iyy="2.3e-6" iyz="0" izz="2.2e-6"/>
    </inertial>
  </link>
  <link name="gen3_robotiq_85_right_knuckle_link">
    <visual>
      <geometry><mesh filename="package://gen3_description/meshes/g2f85_visual/right_knuckle.dae"/></geometry>
    </visual>
    <collision>
      <geometry><mesh filename="package://gen3_description/meshes/g2f85_collision/right_knuckle.stl"/></geometry>
    </collision>
    <inertial>
      <origin rpy="0 0 0" xyz="-0.0121 0.0002 -0.00058"/>
      <mass value="0.0138"/>
      <inertia ixx="3.5e-7" ixy="0.0" ixz="-1.1e-7" iyy="2.3e-6" iyz="0.0" izz="2.2e-6"/>
    </inertial>
  </link>
  <link name="gen3_robotiq_85_left_finger_link">
    <visual>
      <geometry><mesh filename="package://gen3_description/meshes/g2f85_visual/left_finger.dae"/></geometry>
    </visual>
    <collision>
      <geometry><mesh filename="package://gen3_description/meshes/g2f85_collision/left_finger.stl"/></geometry>
    </collision>
    <inertial>
      <origin rpy="0 0 0" xyz="0.0034 -0.00079 0.0186"/>
      <mass value="0.0426"/>
      <inertia ixx="1.38e-05" ixy="0.0" ixz="-2.17e-06" iyy="1.18e-05" iyz="0.0" izz="5.19e-06"/>
    </inertial>
  </link>
  <link name="gen3_robotiq_85_right_finger_link">
    <visual>
      <geometry><mesh filename="package://gen3_description/meshes/g2f85_visual/right_finger.dae"/></geometry>
    </visual>
    <collision>
      <geometry><mesh filename="package://gen3_description/meshes/g2f85_collision/right_finger.stl"/></geometry>
    </collision>
    <inertial>
      <origin rpy="0 0 0" xyz="-0.0034 -5.5e-06 0.0186"/>
      <mass value="0.0426"/>
      <inertia ixx="1.38e-05" ixy="0.0" ixz="2.17e-06" iyy="1.18e-05" iyz="0.0" izz="5.19e-06"/>
    </inertial>
  </link>
  <link name="gen3_robotiq_85_left_inner_knuckle_link">
    <visual>
      <geometry><mesh filename="package://gen3_description/meshes/g2f85_visual/left_inner_knuckle.dae"/></geometry>
    </visual>
    <collision>
      <geometry><mesh filename="package://gen3_description/meshes/g2f85_collision/left_inner_knuckle.stl"/></geometry>
    </collision>
    <inertial>
      <origin rpy="0 0 0" xyz="0.0189 0.00015 0.0224"/>
      <mass value="0.0296"/>
      <inertia ixx="9.57e-06" ixy="0.0" ixz="-3.9e-06" iyy="8.69e-06" iyz="0.0" izz="8.19e-06"/>
    </inertial>
  </link>
  <link name="gen3_robotiq_85_right_inner_knuckle_link">
    <visual>
      <geometry><mesh filename="package://gen3_description/meshes/g2f85_visual/right_inner_knuckle.dae"/></geometry>
    </visual>
    <collision>
      <geometry><mesh filename="package://gen3_description/meshes/g2f85_collision/right_inner_knuckle.stl"/></geometry>
    </collision>
    <inertial>
      <origin rpy="0 0 0" xyz="-0.0192 5e-05 0.0222"/>
      <mass value="0.0296"/>
      <inertia ixx="9.42e-06" ixy="0.0" ixz="3.96e-06" iyy="8.69e-06" iyz="0.0" izz="8.33e-06"/>
    </inertial>
  </link>
  <link name="gen3_robotiq_85_left_finger_tip_link">
    <visual>
      <geometry><mesh filename="package://gen3_description/meshes/g2f85_visual/left_finger_tip.dae"/></geometry>
    </visual>
    <collision>
      <geometry><mesh filename="package://gen3_description/meshes/g2f85_collision/left_finger_tip.stl"/></geometry>
    </collision>
    <inertial>
      <origin rpy="0 0 0" xyz="-0.0145 -0.0008 0.0164"/>
      <mass value="0.0426"/>
      <inertia ixx="1.04e-05" ixy="0.0" ixz="3.52e-6" iyy="1.19e-05" iyz="0.0" izz="4.22e-06"/>
    </inertial>
  </link>
  <link name="gen3_robotiq_85_right_finger_tip_link">
    <visual>
      <geometry><mesh filename="package://gen3_description/meshes/g2f85_visual/right_finger_tip.dae"/></geometry>
    </visual>
    <collision>
      <geometry><mesh filename="package://gen3_description/meshes/g2f85_collision/right_finger_tip.stl"/></geometry>
    </collision>
    <inertial>
      <origin rpy="0 0 0" xyz="0.0145 5e-05 0.0164"/>
      <mass value="0.0426"/>
      <inertia ixx="1.04e-05" ixy="0.0" ixz="-3.52e-06" iyy="1.19e-05" iyz="0.0" izz="4.22e-06"/>
    </inertial>
  </link>
  
  <joint name="gen3_robotiq_85_left_knuckle_joint" type="revolute">
    <parent link="gen3_robotiq_85_base_link"/>
    <child link="gen3_robotiq_85_left_knuckle_link"/>
    <axis xyz="0 -1 0"/>
    <origin rpy="0 0 0" xyz="0.0306 0.0 0.0549"/>
    <limit effort="50" lower="0.0" upper="0.8" velocity="0.5"/>
  </joint>
  <joint name="gen3_robotiq_85_right_knuckle_joint" type="revolute">
    <parent link="gen3_robotiq_85_base_link"/>
    <child link="gen3_robotiq_85_right_knuckle_link"/>
    <axis xyz="0 -1 0"/>
    <origin rpy="0 0 0" xyz="-0.0306 0.0 0.0549"/>
    <limit effort="50" lower="-0.8" upper="0.0" velocity="0.5"/>
    <mimic joint="gen3_robotiq_85_left_knuckle_joint" multiplier="-1"/>
  </joint>
  <joint name="gen3_robotiq_85_left_finger_joint" type="fixed">
    <parent link="gen3_robotiq_85_left_knuckle_link"/>
    <child link="gen3_robotiq_85_left_finger_link"/>
    <origin rpy="0 0 0" xyz="0.0315 0.0 -0.0037"/>
  </joint>
  <joint name="gen3_robotiq_85_right_finger_joint" type="fixed">
    <parent link="gen3_robotiq_85_right_knuckle_link"/>
    <child link="gen3_robotiq_85_right_finger_link"/>
    <origin rpy="0 0 0" xyz="-0.0315 0.0 -0.0037"/>
  </joint>
  <joint name="gen3_robotiq_85_left_inner_knuckle_joint" type="continuous">
    <parent link="gen3_robotiq_85_base_link"/>
    <child link="gen3_robotiq_85_left_inner_knuckle_link"/>
    <axis xyz="0 -1 0"/>
    <origin rpy="0 0 0" xyz="0.0127 0.0 0.06142"/>
    <mimic joint="gen3_robotiq_85_left_knuckle_joint" multiplier="1"/>
  </joint>
  <joint name="gen3_robotiq_85_right_inner_knuckle_joint" type="continuous">
    <parent link="gen3_robotiq_85_base_link"/>
    <child link="gen3_robotiq_85_right_inner_knuckle_link"/>
    <axis xyz="0 -1 0"/>
    <origin rpy="0 0 0" xyz="-0.0127 0.0 0.06142"/>
    <mimic joint="gen3_robotiq_85_left_knuckle_joint" multiplier="-1"/>
  </joint>
  <joint name="gen3_robotiq_85_left_finger_tip_joint" type="continuous">
    <parent link="gen3_robotiq_85_left_finger_link"/>
    <child link="gen3_robotiq_85_left_finger_tip_link"/>
    <axis xyz="0 -1 0"/>
    <origin rpy="0 0 0" xyz="0.0056 0.0 0.0471"/>
    <mimic joint="gen3_robotiq_85_left_knuckle_joint" multiplier="-1"/>
  </joint>
  <joint name="gen3_robotiq_85_right_finger_tip_joint" type="continuous">
    <parent link="gen3_robotiq_85_right_finger_link"/>
    <child link="gen3_robotiq_85_right_finger_tip_link"/>
    <axis xyz="0 -1 0"/>
    <origin rpy="0 0 0" xyz="-0.0056 0.0 0.0471"/>
    <mimic joint="gen3_robotiq_85_left_knuckle_joint" multiplier="1"/>
  </joint>
  
</robot>